#VRML_SIM R2019a utf8
WorldInfo {
}
Viewpoint {
  orientation 0.28826625158922 0.8843413942253385 0.3672095677597262 4.338779857085355
  position -1.3166237429674588 2.2860580205260095 -0.4990719940106455
}
TexturedBackground {
}
TexturedBackgroundLight {
}
Floor {
}
Solid {
  translation 0 0.35 0
  rotation 1 0 0 0.349
  children [
    DEF base Group {
      children [
        DEF tube_ Shape {
          appearance DEF color1 PBRAppearance {
            baseColor 0 0 1
          }
          geometry Cylinder {
            height 0.9
            radius 0.02
          }
        }
        Transform {
          translation 0.5 0 0
          children [
            USE tube_
          ]
        }
        Transform {
          translation 0.25 0 0
          rotation 0 0 1 1.5707
          children [
            DEF tube2 Shape {
              appearance USE color1
              geometry Cylinder {
                height 0.5
                radius 0.02
              }
            }
          ]
        }
      ]
    }
    Group {
      children [
        Transform {
          translation 0 0.2 0.5
          rotation 1 0 0 -0.68
          children [
            USE base
          ]
        }
      ]
    }
  ]
}
Solid {
  translation 0.25 0.79 0.25
  rotation -1 0 0 2.9802322387695313e-08
  children [
    Shape {
      appearance USE color1
      geometry Box {
        size 0.6 0.02 0.6
      }
    }
    Transform {
      translation 0 0.165 0
      children [
        Shape {
          appearance DEF color2 PBRAppearance {
            baseColor 0 1 0
          }
          geometry Cylinder {
            height 0.3
            radius 0.03
          }
        }
        Transform {
          translation 0 0.2 0
          rotation 0 0 1 1.5707
          children [
            Shape {
              appearance USE color2
              geometry Cylinder {
                height 0.2
                radius 0.05
              }
            }
            HingeJoint {
              jointParameters HingeJointParameters {
                axis 0 1 0
                anchor 0 0.1 0
              }
              endPoint Solid {
                translation 0 0.12 0
                rotation 1 0 0 1.5707
                children [
                  Group {
                    children [
                      DEF helice Shape {
                        appearance USE color2
                        geometry Cylinder {
                          height 0.2
                          radius 0.02
                        }
                      }
                      Transform {
                        rotation 0 0 1 1.5707
                        children [
                          USE helice
                        ]
                      }
                      Transform {
                        rotation 0 0 1 2.35
                        children [
                          USE helice
                        ]
                      }
                    ]
                  }
                ]
                physics Physics {
                }
              }
            }
            HingeJoint {
              jointParameters HingeJointParameters {
                anchor 0 -0.1 0
              }
              endPoint Solid {
                translation 0 -0.15 0
                children [
                  DEF cilinder2 Shape {
                    appearance USE color2
                    geometry Cylinder {
                      height 0.1
                      radius 0.01
                    }
                  }
                  Transform {
                    translation 0 -0.1 0
                    children [
                      Shape {
                        appearance USE color2
                        geometry Box {
                          size 0.05 0.1 0.01
                        }
                      }
                    ]
                  }
                ]
                name "solid(1)"
                physics Physics {
                }
              }
            }
          ]
        }
      ]
    }
  ]
  name "solid(1)"
}
