#VRML_SIM R2019a utf8
WorldInfo {
}
Viewpoint {
  orientation -0.057510286957080485 0.9790598674364759 0.19528016506902227 2.54881897823378
  position 4.070428105501969 2.0890982804396674 -5.368951484837934
}
TexturedBackground {
}
TexturedBackgroundLight {
}
Floor {
}
Solid {
  translation 0 0.35 0
  rotation 1 0 0 0.349
  children [
    DEF base Group {
      children [
        DEF tube_ Shape {
          appearance DEF color1 PBRAppearance {
            baseColor 0 0 1
          }
          geometry Cylinder {
            height 0.9
            radius 0.02
          }
        }
        Transform {
          translation 0.5 0 0
          children [
            USE tube_
          ]
        }
        Transform {
          translation 0.25 0 0
          rotation 0 0 1 1.5707
          children [
            DEF tube2 Shape {
              appearance USE color1
              geometry Cylinder {
                height 0.5
                radius 0.02
              }
            }
          ]
        }
      ]
    }
    Group {
      children [
        Transform {
          translation 0 0.2 0.5
          rotation 1 0 0 -0.68
          children [
            USE base
          ]
        }
      ]
    }
  ]
}
Solid {
  translation 0.25 0.79 0.25
  rotation -1 0 0 2.9802322387695313e-08
  children [
    Shape {
      appearance USE color1
      geometry Box {
        size 0.6 0.02 0.6
      }
    }
    Transform {
      translation 0 0.165 0
      children [
        Shape {
          appearance DEF color2 PBRAppearance {
            baseColor 0 1 0
          }
          geometry Cylinder {
            height 0.3
            radius 0.03
          }
        }
        Transform {
          translation 0 0.2 0
          rotation 0 0 1 1.5707
          children [
            Shape {
              appearance USE color2
              geometry Cylinder {
                height 0.2
                radius 0.05
              }
            }
            HingeJoint {
              jointParameters HingeJointParameters {
                axis 0 1 0
                anchor 0 0.1 0
              }
              endPoint Solid {
                children [
                  Group {
                    children [
                      Shape {
                      }
                    ]
                  }
                ]
              }
            }
            HingeJoint {
              jointParameters HingeJointParameters {
                anchor 0 -0.1 0
              }
              endPoint Solid {
                translation 0 -0.15 0
                children [
                  Shape {
                    appearance USE color2
                    geometry Cylinder {
                      height 0.1
                      radius 0.01
                    }
                  }
                  Transform {
                    translation 0 -0.1 0
                    children [
                      Shape {
                        appearance USE color2
                        geometry Box {
                          size 0.05 0.1 0.01
                        }
                      }
                    ]
                  }
                ]
                name "solid(1)"
              }
            }
          ]
        }
      ]
    }
  ]
  name "solid(1)"
}
